Workbook

Sheet Flight Log
A1: Fecha del Vuelo: | B1: Horas de Vuelo | C1: Nº de Vuelos (Ciclos) | D1: Aterrizajes | E1: Horas de Vuelo Acumuladas | F1: Nº de Vuelos (Ciclos) Acumulados | G1: Aterrizajes Totales | H1: Observaciones
A3: 45657 | B3: 0 | C3: 0 | D3: 0 | E3: 2080 | F3: 1040 | G3: 1240 | H3: Saldo inicial simulado para ejercicio academico
A4: 45669 | B4: 1.2 | C4: 1 | D4: 1 | E4: =E3+B4 | F4: =F3+C4 | G4: =G3+D4 | H4: Vuelo local entrenamiento
A5: 45683 | B5: 1.6 | C5: 1 | D5: 1 | E5: =E4+B5 | F5: =F4+C5 | G5: =G4+D5 | H5: Navegacion corta
A6: 45697 | B6: 1.4 | C6: 1 | D6: 2 | E6: =E5+B6 | F6: =F5+C6 | G6: =G5+D6 | H6: Circuitos y toma final
A7: 45711 | B7: 2.1 | C7: 1 | D7: 1 | E7: =E6+B7 | F7: =F6+C7 | G7: =G6+D7 | H7: Navegacion
A8: 45725 | B8: 1.8 | C8: 1 | D8: 1 | E8: =E7+B8 | F8: =F7+C8 | G8: =G7+D8 | H8: Vuelo local
A9: 45746 | B9: 2.4 | C9: 1 | D9: 1 | E9: =E8+B9 | F9: =F8+C9 | G9: =G8+D9 | H9: Navegacion
A10: 45760 | B10: 1.5 | C10: 1 | D10: 1 | E10: =E9+B10 | F10: =F9+C10 | G10: =G9+D10 | H10: Vuelo local
A11: 45774 | B11: 1.9 | C11: 1 | D11: 2 | E11: =E10+B11 | F11: =F10+C11 | G11: =G10+D11 | H11: Entrenamiento
A12: 45788 | B12: 2.2 | C12: 1 | D12: 1 | E12: =E11+B12 | F12: =F11+C12 | G12: =G11+D12 | H12: Navegacion
A13: 45802 | B13: 1.7 | C13: 1 | D13: 1 | E13: =E12+B13 | F13: =F12+C13 | G13: =G12+D13 | H13: Vuelo local
A14: 45823 | B14: 2.6 | C14: 1 | D14: 1 | E14: =E13+B14 | F14: =F13+C14 | G14: =G13+D14 | H14: Navegacion
A15: 45844 | B15: 1.3 | C15: 1 | D15: 2 | E15: =E14+B15 | F15: =F14+C15 | G15: =G14+D15 | H15: Circuitos
... A30: 46152 | B30: 2.1 | C30: 1 | D30: 2 | E30: =E29+B30 | F30: =F29+C30 | G30: =G29+D30 | H30: Vuelo previo al corte del trabajo

Sheet Tasks
A1: Registration | B1: EC-SIM | F1: Date: | G1: =TODAY()
A2: Aircraft Model | B2: Socata TB 10 | G2: Date | H2: Hrs | I2: Ldgs
A3: Serial Number | B3: 649 | F3: Last readout of the Flight Log: | G3: =LOOKUP(2,1/('Flight Log'!$A:$A<>""),'Flight Log'!$A:$A) | H3: =LOOKUP(2,1/('Flight Log'!$E:$E<>""),'Flight Log'!$E:$E) | I3: =LOOKUP(2,1/('Flight Log'!$G:$G<>""),'Flight Log'!$G:$G)
A4: Manufacture Date (Y) | B4: 1988
A5: Scheduled Test/Tasks
B6: Interval | E6: Interval FH/ CyC/Ldgs | H6: Calendar | K6: Applicable ICA reference
A7: Inspection/Check/Task - description | B7: FH | C7: Ldg/Cycle | D7: days | E7: Performed | F7: Next due | G7: to go | H7: Performed | I7: Next due | J7: to go | K7: Document / Revision
A8: A Inspection - First 25 hours | B8: 25 | E8: 25 | F8: Completed | I8: =IF(AND(D8<>"",H8<>""),H8+D8,"") | J8: =IF(I8="","",I8-$G$3) | K8: SOCATA TB 10 MM Rev.18, 05-20-00 / 05-20-02
A9: 2A Inspection / VP50 | B9: 50 | D9: 180 | E9: 2100 | F9: =IF(AND(B9<>"",E9<>""),E9+B9,IF(AND(C9<>"",E9<>""),E9+C9,"")) | G9: =IF(F9="","",F9-IF(B9<>"",$H$3,$I$3)) | H9: 46068 | I9: =IF(AND(D9<>"",H9<>""),H9+D9,"") | J9: =IF(I9="","",I9-$G$3) | K9: SOCATA TB 10 MM Rev.18, 05-20-00 / 05-20-03
A10: 4A Inspection / VP100 | B10: 100 | E10: 2050 | F10: =IF(AND(B10<>"",E10<>""),E10+B10,IF(AND(C10<>"",E10<>""),E10+C10,"")) | G10: =IF(F10="","",F10-IF(B10<>"",$H$3,$I$3)) | I10: =IF(AND(D10<>"",H10<>""),H10+D10,"") | J10: =IF(I10="","",I10-$G$3) | K10: SOCATA TB 10 MM Rev.18, 05-20-00 / 05-20-04
A11: 80A Major Inspection | B11: 2000 | E11: 2000 | F11: =IF(AND(B11<>"",E11<>""),E11+B11,IF(AND(C11<>"",E11<>""),E11+C11,"")) | G11: =IF(F11="","",F11-IF(B11<>"",$H$3,$I$3)) | I11: =IF(AND(D11<>"",H11<>""),H11+D11,"") | J11: =IF(I11="","",I11-$G$3) | K11: SOCATA TB 10 MM Rev.18, 05-20-00 / 05-20-05
A12: Annual Inspection (AI) | D12: 365 | F12: =IF(AND(B12<>"",E12<>""),E12+B12,IF(AND(C12<>"",E12<>""),E12+C12,"")) | G12: =IF(F12="","",F12-IF(B12<>"",$H$3,$I$3)) | H12: 46082 | I12: =IF(AND(D12<>"",H12<>""),H12+D12,"") | J12: =IF(I12="","",I12-$G$3) | K12: SOCATA TB 10 MM Rev.18, 05-20-00 / 05-20-06
A16: Special Points Test/Tasks
B17: Interval | E17: Interval FH/ CyC/Ldgs | H17: Calendar | K17: Applicable ICA reference
A18: Inspection/Check/Task - description | B18: FH | C18: Ldg/Cycle | D18: days | E18: Performed | F18: Next due | G18: to go | H18: Performed | I18: Next due | J18: to go | K18: Document / Revision
A19: Engine special inspection | B19: 400 | E19: 2000 | F19: =IF(AND(B19<>"",E19<>""),E19+B19,IF(AND(C19<>"",E19<>""),E19+C19,"")) | G19: =IF(F19="","",F19-IF(B19<>"",$H$3,$I$3)) | I19: =IF(AND(D19<>"",H19<>""),H19+D19,"") | J19: =IF(I19="","",I19-$G$3) | K19: SOCATA TB 10 MM Rev.18, 05-20-00 / 05-20-01 p.234-235
A20: 500 hrs special inspection | B20: 500 | E20: 2000 | F20: =IF(AND(B20<>"",E20<>""),E20+B20,IF(AND(C20<>"",E20<>""),E20+C20,"")) | G20: =IF(F20="","",F20-IF(B20<>"",$H$3,$I$3)) | I20: =IF(AND(D20<>"",H20<>""),H20+D20,"") | J20: =IF(I20="","",I20-$G$3) | K20: SOCATA TB 10 MM Rev.18, 05-20-00
A21: 1000 hrs special inspection | B21: 1000 | E21: 2000 | F21: =IF(AND(B21<>"",E21<>""),E21+B21,IF(AND(C21<>"",E21<>""),E21+C21,"")) | G21: =IF(F21="","",F21-IF(B21<>"",$H$3,$I$3)) | I21: =IF(AND(D21<>"",H21<>""),H21+D21,"") | J21: =IF(I21="","",I21-$G$3) | K21: SOCATA TB 10 MM Rev.18, 05-20-00
A22: Brake hydraulic fluid change | D22: 1095 | F22: =IF(AND(B22<>"",E22<>""),E22+B22,IF(AND(C22<>"",E22<>""),E22+C22,"")) | G22: =IF(F22="","",F22-IF(B22<>"",$H$3,$I$3)) | H22: 45717 | I22: =IF(AND(D22<>"",H22<>""),H22+D22,"") | J22: =IF(I22="","",I22-$G$3) | K22: SOCATA TB 10 MM Rev.18, 05-20-01 p.219
A23: Fuel selector filtering element | B23: 300 | D23: 365 | E23: 2000 | F23: =IF(AND(B23<>"",E23<>""),E23+B23,IF(AND(C23<>"",E23<>""),E23+C23,"")) | G23: =IF(F23="","",F23-IF(B23<>"",$H$3,$I$3)) | H23: 46068 | I23: =IF(AND(D23<>"",H23<>""),H23+D23,"") | J23: =IF(I23="","",I23-$G$3) | K23: SOCATA TB 10 MM Rev.18, 05-20-01 p.213
A24: Flap actuator/supports visual inspection | B24: 500 | E24: 2000 | F24: =IF(AND(B24<>"",E24<>""),E24+B24,IF(AND(C24<>"",E24<>""),E24+C24,"")) | G24: =IF(F24="","",F24-IF(B24<>"",$H$3,$I$3)) | I24: =IF(AND(D24<>"",H24<>""),H24+D24,"") | J24: =IF(I24="","",I24-$G$3) | K24: SOCATA TB 10 MM Rev.18, 05-20-01 p.212
A25: Flight control supports inspection | B25: 500 | E25: 2000 | F25: =IF(AND(B25<>"",E25<>""),E25+B25,IF(AND(C25<>"",E25<>""),E25+C25,"")) | G25: =IF(F25="","",F25-IF(B25<>"",$H$3,$I$3)) | I25: =IF(AND(D25<>"",H25<>""),H25+D25,"") | J25: =IF(I25="","",I25-$G$3) | K25: SOCATA TB 10 MM Rev.18, 05-20-01 p.225
A26: Elevator hinge bearings inspection | B26: 1000 | D26: 730 | E26: 2000 | F26: =IF(AND(B26<>"",E26<>""),E26+B26,IF(AND(C26<>"",E26<>""),E26+C26,"")) | G26: =IF(F26="","",F26-IF(B26<>"",$H$3,$I$3)) | H26: 45839 | I26: =IF(AND(D26<>"",H26<>""),H26+D26,"") | J26: =IF(I26="","",I26-$G$3) | K26: SOCATA TB 10 MM Rev.18, 05-20-01 p.227
A27: Operational Tasks
B28: Interval | E28: Interval FH/ CyC/Ldgs | H28: Calendar | K28: Applicable ICA reference
A29: Inspection/Check/Task - description | B29: FH | C29: Ldg/Cycle | D29: days | E29: Performed | F29: Next due | G29: to go | H29: Performed | I29: Next due | J29: to go | K29: Document / Revision
A30: Transponder / altimeter calibration/check | D30: 730 | F30: =IF(AND(B30<>"",E30<>""),E30+B30,IF(AND(C30<>"",E30<>""),E30+C30,"")) | G30: =IF(F30="","",F30-IF(B30<>"",$H$3,$I$3)) | H30: 45809 | I30: =IF(AND(D30<>"",H30<>""),H30+D30,"") | J30: =IF(I30="","",I30-$G$3) | K30: SOCATA TB 10 MM Rev.18, 05-10-00 p.3 / 05-20-01 p.221,223
A31: Weighing and balancing | D31: 1825 | F31: =IF(AND(B31<>"",E31<>""),E31+B31,IF(AND(C31<>"",E31<>""),E31+C31,"")) | G31: =IF(F31="","",F31-IF(B31<>"",$H$3,$I$3)) | H31: 45306 | I31: =IF(AND(D31<>"",H31<>""),H31+D31,"") | J31: =IF(I31="","",I31-$G$3) | K31: SOCATA TB 10 MM Rev.18, 05-20-00 p.2 / 05-20-01 p.202
A32: Compass compensation | D32: 1095 | F32: =IF(AND(B32<>"",E32<>""),E32+B32,IF(AND(C32<>"",E32<>""),E32+C32,"")) | G32: =IF(F32="","",F32-IF(B32<>"",$H$3,$I$3)) | H32: 45901 | I32: =IF(AND(D32<>"",H32<>""),H32+D32,"") | J32: =IF(I32="","",I32-$G$3) | K32: SOCATA TB 10 MM Rev.18, 05-20-00 p.2 / 05-20-01 p.222
A33: Air data systems tightness test | B33: 300 | D33: 1095 | E33: 2100 | F33: =IF(AND(B33<>"",E33<>""),E33+B33,IF(AND(C33<>"",E33<>""),E33+C33,"")) | G33: =IF(F33="","",F33-IF(B33<>"",$H$3,$I$3)) | H33: 45809 | I33: =IF(AND(D33<>"",H33<>""),H33+D33,"") | J33: =IF(I33="","",I33-$G$3) | K33: SOCATA TB 10 MM Rev.18, 05-20-01 p.222
A34: ELT visual inspection and operational test | B34: 100 | D34: 180 | E34: 2100 | F34: =IF(AND(B34<>"",E34<>""),E34+B34,IF(AND(C34<>"",E34<>""),E34+C34,"")) | G34: =IF(F34="","",F34-IF(B34<>"",$H$3,$I$3)) | H34: 46068 | I34: =IF(AND(D34<>"",H34<>""),H34+D34,"") | J34: =IF(I34="","",I34-$G$3) | K34: SOCATA TB 10 MM Rev.18 05-20-01; operational ELT check tracked independently
A36: Lubrication & Cleaning Tasks
B37: Interval | E37: Interval FH/ CyC/Ldgs | H37: Calendar | K37: Applicable ICA reference
A38: Inspection/Check/Task - description | B38: FH | C38: Ldg/Cycle | D38: days | E38: Performed | F38: Next due | G38: to go | H38: Performed | I38: Next due | J38: to go | K38: Document / Revision
A39: Drain oil system / filter / crankcase strainer | B39: 50 | D39: 120 | E39: 2100 | F39: =IF(AND(B39<>"",E39<>""),E39+B39,IF(AND(C39<>"",E39<>""),E39+C39,"")) | G39: =IF(F39="","",F39-IF(B39<>"",$H$3,$I$3)) | H39: 46101 | I39: =IF(AND(D39<>"",H39<>""),H39+D39,"") | J39: =IF(I39="","",I39-$G$3) | K39: SOCATA TB 10 MM Rev.18, 05-20-01 p.203 ATA 12-10
A40: Drain fuel tanks and fuel system / ventilate | B40: 2000 | D40: 365 | E40: 2000 | F40: =IF(AND(B40<>"",E40<>""),E40+B40,IF(AND(C40<>"",E40<>""),E40+C40,"")) | G40: =IF(F40="","",F40-IF(B40<>"",$H$3,$I$3)) | H40: 46082 | I40: =IF(AND(D40<>"",H40<>""),H40+D40,"") | J40: =IF(I40="","",I40-$G$3) | K40: SOCATA TB 10 MM Rev.18, 05-20-01 p.203 ATA 12-10
A41: Clean exterior surface / inspect corrosion | B41: 100 | D41: 365 | E41: 2100 | F41: =IF(AND(B41<>"",E41<>""),E41+B41,IF(AND(C41<>"",E41<>""),E41+C41,"")) | G41: =IF(F41="","",F41-IF(B41<>"",$H$3,$I$3)) | H41: 46101 | I41: =IF(AND(D41<>"",H41<>""),H41+D41,"") | J41: =IF(I41="","",I41-$G$3) | K41: SOCATA TB 10 MM Rev.18, 05-20-01 p.203 ATA 12-20
A42: Clean engine | B42: 100 | D42: 365 | E42: 2100 | F42: =IF(AND(B42<>"",E42<>""),E42+B42,IF(AND(C42<>"",E42<>""),E42+C42,"")) | G42: =IF(F42="","",F42-IF(B42<>"",$H$3,$I$3)) | H42: 46101 | I42: =IF(AND(D42<>"",H42<>""),H42+D42,"") | J42: =IF(I42="","",I42-$G$3) | K42: SOCATA TB 10 MM Rev.18, 05-20-01 p.203 ATA 12-20
A43: Anticorrosion/lubrication cockpit-fuselage & landing gear | B43: 50 | D43: 365 | E43: 2100 | F43: =IF(AND(B43<>"",E43<>""),E43+B43,IF(AND(C43<>"",E43<>""),E43+C43,"")) | G43: =IF(F43="","",F43-IF(B43<>"",$H$3,$I$3)) | H43: 46101 | I43: =IF(AND(D43<>"",H43<>""),H43+D43,"") | J43: =IF(I43="","",I43-$G$3) | K43: SOCATA TB 10 MM Rev.18, 05-20-01 p.203-204 ATA 20-00
A44: Anticorrosion/lubrication stabilizers/wings/engine compartment | B44: 100 | D44: 365 | E44: 2100 | F44: =IF(AND(B44<>"",E44<>""),E44+B44,IF(AND(C44<>"",E44<>""),E44+C44,"")) | G44: =IF(F44="","",F44-IF(B44<>"",$H$3,$I$3)) | H44: 46101 | I44: =IF(AND(D44<>"",H44<>""),H44+D44,"") | J44: =IF(I44="","",I44-$G$3) | K44: SOCATA TB 10 MM Rev.18, 05-20-01 p.204 ATA 20-00
...

Sheet Life Limit Comp
A1: Registration | C1: EC-SIM | G1: Date: | H1: =TODAY()
A2: Aircraft Model | C2: Socata TB 10 | H2: Date | I2: Hrs | J2: Ldgs
A3: Serial Number | C3: 649 | G3: Last readout of the Flight Log: | H3: =LOOKUP(2,1/('Flight Log'!$A:$A<>""),'Flight Log'!$A:$A) | I3: =LOOKUP(2,1/('Flight Log'!$E:$E<>""),'Flight Log'!$E:$E) | J3: =LOOKUP(2,1/('Flight Log'!$G:$G<>""),'Flight Log'!$G:$G)
A4: Manufacture Date (Y) | C4: 1988
A5: Life Limited Items
C6: Interval /TBO | F6: Interval FH/ CyC/Ldgs | I6: Calendar | M6: Applicable ICA reference
A7: Item | B7: Model | C7: FH | D7: Ldg/Cycle | E7: days | F7: Performed | G7: Next due | H7: to go | I7: Performed | J7: Next due | K7: to go | L7: Type of Task (OH, Discard, On Condition) | M7: Document / Revision
A8: Motor | B8: Lycoming O-360-A1AD | C8: 2000 | E8: 4380 | F8: 1000 | G8: =IF(AND(C8<>"",F8<>""),F8+C8,IF(AND(D8<>"",F8<>""),F8+D8,"")) | H8: =IF(G8="","",G8-IF(C8<>"",$I$3,$J$3)) | I8: 43115 | J8: =IF(AND(E8<>"",I8<>""),I8+E8,"") | K8: =IF(J8="","",J8-$H$3) | L8: OH | M8: Lycoming SI 1009BE p.2,p.3; SOCATA TB10 MM Rev.18 05-10-00 p.4
A9: Alternator | B9: ALX 8421 / ALX 8521 / ALU 8421 | C9: 2000 | E9: 4380 | F9: 1000 | G9: =IF(AND(C9<>"",F9<>""),F9+C9,IF(AND(D9<>"",F9<>""),F9+D9,"")) | H9: =IF(G9="","",G9-IF(C9<>"",$I$3,$J$3)) | I9: 43115 | J9: =IF(AND(E9<>"",I9<>""),I9+E9,"") | K9: =IF(J9="","",J9-$H$3) | L9: OH | M9: SOCATA TB10 MM Rev.18 05-10-00 p.1
A10: Propeller | B10: Hartzell HC-C2YK-1BF/F7666 A-2 | G10: =IF(AND(C10<>"",F10<>""),F10+C10,IF(AND(D10<>"",F10<>""),F10+D10,"")) | H10: =IF(G10="","",G10-IF(C10<>"",$I$3,$J$3)) | J10: =IF(AND(E10<>"",I10<>""),I10+E10,"") | K10: =IF(J10="","",J10-$H$3) | L10: OH | M10: SOCATA TB10 MM Rev.18 05-10-00 p.4
A11: Propeller governor | B11: Hartzell F4-26 | C11: 2000 | E11: 4380 | F11: 1000 | G11: =IF(AND(C11<>"",F11<>""),F11+C11,IF(AND(D11<>"",F11<>""),F11+D11,"")) | H11: =IF(G11="","",G11-IF(C11<>"",$I$3,$J$3)) | I11: 43115 | J11: =IF(AND(E11<>"",I11<>""),I11+E11,"") | K11: =IF(J11="","",J11-$H$3) | L11: OH | M11: SOCATA TB10 MM Rev.18 05-10-00 p.4
A12: Carburetor | B12: Marvel 71098 MA-4-5 | C12: 2000 | E12: 4380 | F12: 1000 | G12: =IF(AND(C12<>"",F12<>""),F12+C12,IF(AND(D12<>"",F12<>""),F12+D12,"")) | H12: =IF(G12="","",G12-IF(C12<>"",$I$3,$J$3)) | I12: 43115 | J12: =IF(AND(E12<>"",I12<>""),I12+E12,"") | K12: =IF(J12="","",J12-$H$3) | L12: OH | M12: SOCATA TB10 MM Rev.18 05-10-00 p.4
A13: Dual magneto | B13: TCM D4LN3000 | C13: 2000 | E13: 1460 | F13: 2000 | G13: =IF(AND(C13<>"",F13<>""),F13+C13,IF(AND(D13<>"",F13<>""),F13+D13,"")) | H13: =IF(G13="","",G13-IF(C13<>"",$I$3,$J$3)) | I13: 45444 | J13: =IF(AND(E13<>"",I13<>""),I13+E13,"") | K13: =IF(J13="","",J13-$H$3) | L13: OH | M13: SOCATA TB10 MM Rev.18 05-10-00 p.4
A14: Starter | B14: MZ 4222 / Lycoming LW15571 | C14: 2000 | E14: 4380 | F14: 1000 | G14: =IF(AND(C14<>"",F14<>""),F14+C14,IF(AND(D14<>"",F14<>""),F14+D14,"")) | H14: =IF(G14="","",G14-IF(C14<>"",$I$3,$J$3)) | I14: 43115 | J14: =IF(AND(E14<>"",I14<>""),I14+E14,"") | K14: =IF(J14="","",J14-$H$3) | L14: OH | M14: SOCATA TB10 MM Rev.18 05-10-00 p.4
A15: ELT battery assembly | B15: As installed | E15: 1460 | G15: =IF(AND(C15<>"",F15<>""),F15+C15,IF(AND(D15<>"",F15<>""),F15+D15,"")) | H15: =IF(G15="","",G15-IF(C15<>"",$I$3,$J$3)) | I15: 45474 | J15: =IF(AND(E15<>"",I15<>""),I15+E15,"") | K15: =IF(J15="","",J15-$H$3) | L15: Discard | M15: SOCATA TB10 MM Rev.18 05-10-00 p.1-2
A16: ELT seals | B16: ELT90/91/96/97 seals | E16: 4380 | G16: =IF(AND(C16<>"",F16<>""),F16+C16,IF(AND(D16<>"",F16<>""),F16+D16,"")) | H16: =IF(G16="","",G16-IF(C16<>"",$I$3,$J$3)) | I16: 43115 | J16: =IF(AND(E16<>"",I16<>""),I16+E16,"") | K16: =IF(J16="","",J16-$H$3) | L16: Discard | M16: SOCATA TB10 MM Rev.18 05-10-00 p.2
A17: Fire extinguisher | B17: MAIP/AREOFEU/LHOTELLIER as installed | E17: 3650 | G17: =IF(AND(C17<>"",F17<>""),F17+C17,IF(AND(D17<>"",F17<>""),F17+D17,"")) | H17: =IF(G17="","",G17-IF(C17<>"",$I$3,$J$3)) | I17: 45306 | J17: =IF(AND(E17<>"",I17<>""),I17+E17,"") | K17: =IF(J17="","",J17-$H$3) | L17: Discard/Inspection | M17: SOCATA TB10 MM Rev.18 05-10-00 p.3 TR006.05
A18: Vacuum system filter | B18: AIRBORNE 1J4-7 | C18: 500 | E18: 365 | F18: 2100 | G18: =IF(AND(C18<>"",F18<>""),F18+C18,IF(AND(D18<>"",F18<>""),F18+D18,"")) | H18: =IF(G18="","",G18-IF(C18<>"",$I$3,$J$3)) | I18: 46101 | J18: =IF(AND(E18<>"",I18<>""),I18+E18,"") | K18: =IF(J18="","",J18-$H$3) | L18: Discard | M18: SOCATA TB10 MM Rev.18 05-10-00 p.3
A19: Emergency vacuum pump | B19: AIRBORNE 4A3-1 14V | E19: 3650 | G19: =IF(AND(C19<>"",F19<>""),F19+C19,IF(AND(D19<>"",F19<>""),F19+D19,"")) | H19: =IF(G19="","",G19-IF(C19<>"",$I$3,$J$3)) | I19: 43115 | J19: =IF(AND(E19<>"",I19<>""),I19+E19,"") | K19: =IF(J19="","",J19-$H$3) | L19: Discard | M19: SOCATA TB10 MM Rev.18 05-10-00 p.3
A20: Access door latches | B20: TB10 25012102 | C20: 1500 | F20: 1000 | G20: =IF(AND(C20<>"",F20<>""),F20+C20,IF(AND(D20<>"",F20<>""),F20+D20,"")) | H20: =IF(G20="","",G20-IF(C20<>"",$I$3,$J$3)) | J20: =IF(AND(E20<>"",I20<>""),I20+E20,"") | K20: =IF(J20="","",J20-$H$3) | L20: Discard | M20: SOCATA TB10 MM Rev.18 05-10-00 p.3
A21: Teflon hoses | B21: Teflon hoses | G21: =IF(AND(C21<>"",F21<>""),F21+C21,IF(AND(D21<>"",F21<>""),F21+D21,"")) | H21: =IF(G21="","",G21-IF(C21<>"",$I$3,$J$3)) | J21: =IF(AND(E21<>"",I21<>""),I21+E21,"") | K21: =IF(J21="","",J21-$H$3) | L21: On Condition | M21: SOCATA TB10 MM Rev.18 05-10-00 p.5-9
A22: Fuel selector filter/drain hose | B22: Fuel selector filter/drain hose | C22: 2000 | E22: 3650 | F22: 2000 | G22: =IF(AND(C22<>"",F22<>""),F22+C22,IF(AND(D22<>"",F22<>""),F22+D22,"")) | H22: =IF(G22="","",G22-IF(C22<>"",$I$3,$J$3)) | I22: 43115 | J22: =IF(AND(E22<>"",I22<>""),I22+E22,"") | K22: =IF(J22="","",J22-$H$3) | L22: Discard | M22: SOCATA TB10 MM Rev.18 05-10-00 p.5-9; AMP 10.1
A23: Elastomer/rubber/vinyl hoses | B23: Assorted | G23: =IF(AND(C23<>"",F23<>""),F23+C23,IF(AND(D23<>"",F23<>""),F23+D23,"")) | H23: =IF(G23="","",G23-IF(C23<>"",$I$3,$J$3)) | I23: 44941 | J23: =IF(AND(E23<>"",I23<>""),I23+E23,"") | K23: =IF(J23="","",J23-$H$3) | L23: Discard | M23: SOCATA TB10 MM Rev.18 05-10-00 p.5-9
A27: AIRWORTHINESS LIMITATIONS Items
C28: Interval /TBO | F28: Interval FH/ CyC/Ldgs | I28: Calendar | M28: Applicable ICA reference
A29: Item | B29: Model | C29: FH | D29: Ldg/Cycle | E29: days | F29: Performed | G29: Next due | H29: to go | I29: Performed | J29: Next due | K29: to go | L29: Type of Task (OH, Discard, On Condition) | M29: Document / Revision
A30: STRUCTURE SERVICE LIFE
A31: Engine and Nose Landing Gear mounts | B31: TB9/TB10/TB200 mounts | C31: 10000 | F31: 0 | G31: =IF(AND(C31<>"",F31<>""),F31+C31,IF(AND(D31<>"",F31<>""),F31+D31,"")) | H31: =IF(G31="","",G31-IF(C31<>"",$I$3,$J$3)) | J31: =IF(AND(E31<>"",I31<>""),I31+E31,"") | K31: =IF(J31="","",J31-$H$3) | L31: Discard / Airworthiness Limitation | M31: EASA AD 2007-0034; AMM Rev.18 ALS/time limits
A35: ENGINE MOUNT AND LANDING GEAR MOUNT SERVICE LIFE

Sheet ADs
A1: Registration | D1: EC-SIM | H1: Date: | I1: =TODAY()
A2: Aircraft Model | D2: Socata TB 10 | I2: Date | J2: Hrs | K2: Cycles | L2: Ldgs
A3: Serial Number | D3: 649 | H3: Last readout of the Flight Log: | I3: =LOOKUP(2,1/('Flight Log'!$A:$A<>""),'Flight Log'!$A:$A) | J3: =LOOKUP(2,1/('Flight Log'!$E:$E<>""),'Flight Log'!$E:$E) | K3: =LOOKUP(2,1/('Flight Log'!$F:$F<>""),'Flight Log'!$F:$F) | L3: =LOOKUP(2,1/('Flight Log'!$G:$G<>""),'Flight Log'!$G:$G)
A4: Manufacture Date (Y) | D4: 1988
A5: Airworthiness Directives
A6: Aircraft
D7: Interval /TBO | G7: Interval FH/ CyC/Ldgs | J7: Calendar | M7: Applicable ICA reference
A8: AD Number | B8: NAA | C8: Subject | D8: FH | E8: Ldg/Cycle | F8: days | G8: Performed | H8: Next due | I8: to go | J8: Performed | K8: Next due | L8: to go | M8: Remarks
A9: EASA 2007-0034 | B9: EASA | C9: Time Limits - engine and NLG mounts | M9: Applicable. Introduces 10000 FH life limit; controlled in Life Limit/ALI.
A10: EASA 2007-0101 | B10: EASA | C10: Cabin access door hooks | D10: 110 | G10: 2080 | H10: =IF(AND(D10<>"",G10<>""),G10+D10,IF(AND(E10<>"",G10<>""),G10+E10,"")) | I10: =IF(H10="","",H10-IF(D10<>"",$J$3,$L$3)) | K10: =IF(AND(F10<>"",J10<>""),J10+F10,"") | L10: =IF(K10="","",K10-$I$3) | M10: Uncertain: applies if aluminium/AU4G cabin access door hooks installed. Repetitive until terminating action.
A11: EASA 2015-0130 | B11: EASA | C11: Horizontal stabilizer spar inspection | F11: 2190 | H11: =IF(AND(D11<>"",G11<>""),G11+D11,IF(AND(E11<>"",G11<>""),G11+E11,"")) | I11: =IF(H11="","",H11-IF(D11<>"",$J$3,$L$3)) | J11: 45413 | K11: =IF(AND(F11<>"",J11<>""),J11+F11,"") | L11: =IF(K11="","",K11-$I$3) | M11: Applicable to all TB10 S/N. Repetitive 72 months.
A12: EASA 2018-0030R1 | B12: EASA | C12: Wing front attachments inspection/modification | D12: 2000 | E12: 3000 | G12: 2000 | H12: =IF(AND(D12<>"",G12<>""),G12+D12,IF(AND(E12<>"",G12<>""),G12+E12,"")) | I12: =IF(H12="","",H12-IF(D12<>"",$J$3,$L$3)) | K12: =IF(AND(F12<>"",J12<>""),J12+F12,"") | L12: =IF(K12="","",K12-$I$3) | M12: Applicable Group 1: TB10 MSN 001-803 includes S/N 649. Repetitive 2000 FH/3000 LDG; other actions per AD.
A13: EASA 2025-0160 | B13: EASA | C13: Lower rudder hinge fitting inspection | F13: 365 | H13: =IF(AND(D13<>"",G13<>""),G13+D13,IF(AND(E13<>"",G13<>""),G13+E13,"")) | I13: =IF(H13="","",H13-IF(D13<>"",$J$3,$L$3)) | J13: 45870 | K13: =IF(AND(F13<>"",J13<>""),J13+F13,"") | L13: =IF(K13="","",K13-$I$3) | M13: Applicable to all TB10 S/N. Repetitive 12 months.
A14: DGAC F-1992-206R3 | B14: DGAC | C14: Exhaust system | M14: Applicable by S/N 1-1191; no repetitive requirement identified.
A15: DGAC F-1994-264R1 | B15: DGAC | C15: Wing front attachments | M15: N/A: superseded by EASA 2018-0030R1.
A16: DGAC F-1994-265R4 | B16: DGAC | C16: Main landing gear support ribs | D16: 1000 | E16: 1500 | G16: 2000 | H16: =IF(AND(D16<>"",G16<>""),G16+D16,IF(AND(E16<>"",G16<>""),G16+E16,"")) | I16: =IF(H16="","",H16-IF(D16<>"",$J$3,$L$3)) | K16: =IF(AND(F16<>"",J16<>""),J16+F16,"") | L16: =IF(K16="","",K16-$I$3) | M16: Applicable/conditional Case A for TB10 S/N 1-803; repetitive 1000 FH/1500 LDG unless reinforced/kit case applies.
A17: DGAC F-1996-143 | B17: DGAC | C17: Front belt upper attachment | M17: Uncertain: S/N range includes 649 but depends on upholstering on upper duct posts.
A18: DGAC F-1999-062 | B18: DGAC | C18: Fuel system / 14V fuel gauge placard | M18: Uncertain: S/N 649 in 14V range; depends on engine control panel amendment D.
A19: DGAC F-2001-002 | B19: DGAC | C19: Rudder bearing | M19: N/A: superseded by EASA 2025-0160.
A20: DGAC F-2001-005 | B20: DGAC | C20: Seat unlocking | M20: Uncertain: applies unless MOD 165 embodied in production.
A21: DGAC F-2001-305 | B21: DGAC | C21: Nose gear fork spare part | M21: Uncertain: only if affected spare fork installed.
A22: DGAC F-2001-306 | B22: DGAC | C22: Nose gear fork / affected spare part | M22: Uncertain: only if affected spare nose gear fork installed; no repetitive interval identified.
A23: DGAC F-2001-446R1 | B23: DGAC | C23: Ammeter circuit option | M23: Uncertain: depends on ammeter option OPT 10 593/689/D689 installed.
A24: DGAC F-2003-368R2 | B24: DGAC | C24: Aileron/elevator gimbal joints | D24: 110 | F24: 420 | G24: 2080 | H24: =IF(AND(D24<>"",G24<>""),G24+D24,IF(AND(E24<>"",G24<>""),G24+E24,"")) | I24: =IF(H24="","",H24-IF(D24<>"",$J$3,$L$3)) | J24: 46037 | K24: =IF(AND(F24<>"",J24<>""),J24+F24,"") | L24: =IF(K24="","",K24-$I$3) | M24: Uncertain: applies unless MOD 10-0209-27 or terminating SB action embodied; repetitive 110 FH/14 months.
A26: Engine
D27: Interval /TBO | G27: Interval FH/ CyC/Ldgs | J27: Calendar | M27: Applicable ICA reference
A28: AD Number | B28: NAA | C28: Subject | D28: FH | E28: Ldg/Cycle | F28: days | G28: Performed | H28: Next due | I28: to go | J28: Performed | K28: Next due | L28: to go | M28: Remarks
A29: EASA 2005-0023R3 | B29: EASA | C29: Exhaust valve and guide inspection | D29: 440 | G29: 2000 | H29: =IF(AND(D29<>"",G29<>""),G29+D29,IF(AND(E29<>"",G29<>""),G29+E29,"")) | I29: =IF(H29="","",H29-IF(D29<>"",$J$3,$L$3)) | K29: =IF(AND(F29<>"",J29<>""),J29+F29,"") | L29: =IF(K29="","",K29-$I$3) | M29: Applicable: all Lycoming piston engines; repetitive if no Hi-Chrome guides.
A30: EASA 2024-0111 | B30: EASA | C30: Reciprocating engine inspection | M30: Uncertain: depends on manufacture/overhaul date and TCCA AD CF-2005-40 criteria.
A31: FAA 2002-12-07 | B31: FAA | C31: Oil filter converter plate gasket | D31: 50 | G31: 2080 | H31: =IF(AND(D31<>"",G31<>""),G31+D31,IF(AND(E31<>"",G31<>""),G31+E31,"")) | I31: =IF(H31="","",H31-IF(D31<>"",$J$3,$L$3)) | K31: =IF(AND(F31<>"",J31<>""),J31+F31,"") | L31: =IF(K31="","",K31-$I$3) | M31: Uncertain: O-360-A1AD listed; applies by shipping date or affected gasket/kit until terminating action.
A32: FAA 2004-10-14 | B32: FAA | C32: Crankshaft gear retaining bolt | M32: Applicable only after propeller strike event; not repetitive.
A33: FAA 2005-19-11 | B33: FAA | C33: Crankshaft replacement | M33: Uncertain: depends on manufacture/rebuild/overhaul date or crankshaft installation.
A34: FAA 2005-26-10 | B34: FAA | C34: ECi Classic Cast cylinders | M34: Uncertain: depends on affected ECi cylinders installed.
A35: FAA 2006-10-21 | B35: FAA | C35: ECi connecting rods | M35: Uncertain: depends on affected ECi connecting rods installed.
A36: FAA 2006-12-07 | B36: FAA | C36: ECi Classic Cast cylinders | M36: Uncertain: depends on affected ECi cylinders installed.
A37: FAA 2006-20-09 | B37: FAA | C37: Crankshaft replacement | M37: Uncertain/superseded logic: depends on MSB listed engine/crankshaft S/N; see FAA 2012-19-01.
A38: FAA 2007-04-19R1 | B38: FAA | C38: Superior Air Parts cylinders | M38: Uncertain: depends on affected SAP cylinders installed.
A39: FAA 2008-19-05 | B39: FAA | C39: ECi Titan cylinders | D39: 50 | G39: 2080 | H39: =IF(AND(D39<>"",G39<>""),G39+D39,IF(AND(E39<>"",G39<>""),G39+E39,"")) | I39: =IF(H39="","",H39-IF(D39<>"",$J$3,$L$3)) | K39: =IF(AND(F39<>"",J39<>""),J39+F39,"") | L39: =IF(K39="","",K39-$I$3) | M39: Uncertain: O-360-A1AD listed; repetitive if affected ECi Titan cylinders installed.
A40: FAA 2009-26-12 | B40: FAA | C40: ECi Titan cylinders | D40: 50 | G40: 2080 | H40: =IF(AND(D40<>"",G40<>""),G40+D40,IF(AND(E40<>"",G40<>""),G40+E40,"")) | I40: =IF(H40="","",H40-IF(D40<>"",$J$3,$L$3)) | K40: =IF(AND(F40<>"",J40<>""),J40+F40,"") | L40: =IF(K40="","",K40-$I$3) | M40: Uncertain: O-360-A1AD listed; repetitive if affected ECi Titan cylinders installed.
A41: FAA 2010-07-08 | B41: FAA | C41: KAES rebuilt turbochargers | M41: N/A: O-360-A1AD is naturally aspirated, no turbocharger.
...
